Workbook

Sheet 00_使用说明
A1: 团队成员年度学习计划模板 - 使用说明 V1.3
A2: 基于能力胜任模型，完成能力自评、差距识别、年度学习计划制定与执行跟踪
A4: 一、这个模板用于什么 | D4: 二、掌握度评分标准
A5: 用途 | B5: 帮助团队成员基于能力模型识别需要补充的能力项，选择学习材料，制定 1 年周期、可跟踪、可验收的学习计划。 | D5: 掌握度 | E5: 说明 | F5: 职级参考
A6: 适用对象 | B6: 技术架构与开发专业线成员；当前能力模型覆盖 P01 Data Infra、P02 AI Infra / Agent、P03 Coding、C01 基本办公、C02 沟通协作、C03 学习创新。 | D6: 0 | E6: 未接触 / 不具备可验证输出 | F6: -
A7: 核心原则 | B7: 以“三级能力项”为计划和跟踪的最小单元；学习结果应尽量有实操、Demo、脚本、配置截图、验证报告或可检查文档。 | D7: 1 | E7: 了解概念，需要他人指导或协助 | F7: 入门
D8: 2 | E8: 标准场景可独立执行，有基础实操输出 | F8: P4
D9: 3 | E9: 能处理常见问题，能闭环基础异常 | F9: P5
D10: 4 | E10: 能设计方案、组织实施并处理复杂场景 | F10: P6
D11: 5 | E11: 能主导复杂项目，沉淀规范、模板和方法论 | F11: P7-P8
A13: 三、填写流程
A14: 步骤 | B14: 操作位置 | C14: 填写 / 查看内容 | D14: 结果
A15: 1 | B15: 02_能力差距自评 | C15: 填写当前掌握度、目标掌握度、优先级；将“是否纳入计划”选择为“是”。 | D15: 选出年度需要补齐的能力范围。
A16: 2 | B16: 03_年度学习计划 | C16: 自动拉取 02 中入选能力项；手填计划开始、计划截止、目标月份等计划信息。 | D16: 形成年度学习计划清单。
A17: 3 | B17: 04_学习执行跟踪 | C17: 自动同步 03 的计划项；维护执行状态、实际开始 / 完成、实际耗时、证据链接、完成质量、复盘结论和下步动作。 | D17: 形成学习执行记录和年度成长档案。
A18: 4 | B18: 05_月度复盘 | C18: 按月查看计划数、完成数、完成率、耗时和复盘记录。 | D18: 形成月度复盘与改进闭环。
A20: 四、02 → 03 → 04 的关系
A21: 02_能力差距自评 | B21: 选择需要补齐的三级能力项；不要在 02 中写详细执行记录。
A22: 03_年度学习计划 | B22: 自动生成年度计划清单；用于安排年度 / 季度 / 月度节奏。
A23: 04_学习执行跟踪 | B23: 与 03 一对一同步，不再拆分更细任务；用于记录执行状态、证据、完成质量和复盘结论。
A25: 五、完成判定
A26: 基本判定 | B26: 一条学习计划建议同时满足：状态为“已完成”；有证据链接或文件说明；有复盘结论；如未产出可检查材料，不建议判定为完成。
A27: 维护建议 | B27: 先尽量固定 02/03 年度计划范围，再进入 04 跟踪执行；如中途大幅调整 02 的入选范围，需复核 04 中手填状态和证据是否仍对应正确能力项。

Sheet 01_学习计划看板
A1: 个人年度学习计划看板
A3: 成员姓名 | D3: 月份 | E3: 计划任务数 | F3: 完成任务数 | G3: 完成率 | H3: 实际耗时(h)
A4: 当前职级 | D4: 第1月 | E4: ='05_月度复盘'!B2 -> 0 | F4: ='05_月度复盘'!C2 -> 0 | G4: ='05_月度复盘'!D2 -> 0 | H4: ='05_月度复盘'!F2 -> 0
A5: 目标职级 | D5: 第2月 | E5: ='05_月度复盘'!B3 -> 0 | F5: ='05_月度复盘'!C3 -> 0 | G5: ='05_月度复盘'!D3 -> 0 | H5: ='05_月度复盘'!F3 -> 0
A6: 计划开始日期 | D6: 第3月 | E6: ='05_月度复盘'!B4 -> 0 | F6: ='05_月度复盘'!C4 -> 0 | G6: ='05_月度复盘'!D4 -> 0 | H6: ='05_月度复盘'!F4 -> 0
A7: 计划周期 | B7: 12个月 | D7: 第4月 | E7: ='05_月度复盘'!B5 -> 0 | F7: ='05_月度复盘'!C5 -> 0 | G7: ='05_月度复盘'!D5 -> 0 | H7: ='05_月度复盘'!F5 -> 0
D8: 第5月 | E8: ='05_月度复盘'!B6 -> 0 | F8: ='05_月度复盘'!C6 -> 0 | G8: ='05_月度复盘'!D6 -> 0 | H8: ='05_月度复盘'!F6 -> 0
D9: 第6月 | E9: ='05_月度复盘'!B7 -> 0 | F9: ='05_月度复盘'!C7 -> 0 | G9: ='05_月度复盘'!D7 -> 0 | H9: ='05_月度复盘'!F7 -> 0
A10: 能力项总数 | B10: =COUNTA('02_能力差距自评'!F:F)-1 -> 310 | D10: 第7月 | E10: ='05_月度复盘'!B8 -> 0 | F10: ='05_月度复盘'!C8 -> 0 | G10: ='05_月度复盘'!D8 -> 0 | H10: ='05_月度复盘'!F8 -> 0
A11: 纳入计划项数 | B11: =COUNTIF('02_能力差距自评'!P:P,"是") -> 0 | D11: 第8月 | E11: ='05_月度复盘'!B9 -> 0 | F11: ='05_月度复盘'!C9 -> 0 | G11: ='05_月度复盘'!D9 -> 0 | H11: ='05_月度复盘'!F9 -> 0
A12: 年度计划任务数 | B12: =COUNTIF('03_年度学习计划'!D:D,"<>")-1 -> 349 | D12: 第9月 | E12: ='05_月度复盘'!B10 -> 0 | F12: ='05_月度复盘'!C10 -> 0 | G12: ='05_月度复盘'!D10 -> 0 | H12: ='05_月度复盘'!F10 -> 0
A13: 已完成任务数 | B13: =COUNTIFS('03_年度学习计划'!D:D,"<>",'03_年度学习计划'!O:O,"已完成") -> 0 | D13: 第10月 | E13: ='05_月度复盘'!B11 -> 0 | F13: ='05_月度复盘'!C11 -> 0 | G13: ='05_月度复盘'!D11 -> 0 | H13: ='05_月度复盘'!F11 -> 0
A14: 任务完成率 | B14: =IFERROR(B13/B12,0) -> 0 | D14: 第11月 | E14: ='05_月度复盘'!B12 -> 0 | F14: ='05_月度复盘'!C12 -> 0 | G14: ='05_月度复盘'!D12 -> 0 | H14: ='05_月度复盘'!F12 -> 0
A15: 计划耗时(h) | B15: =SUM('03_年度学习计划'!M:M) -> 0 | D15: 第12月 | E15: ='05_月度复盘'!B13 -> 0 | F15: ='05_月度复盘'!C13 -> 0 | G15: ='05_月度复盘'!D13 -> 0 | H15: ='05_月度复盘'!F13 -> 0
A16: 实际耗时(h) | B16: =SUM('03_年度学习计划'!N:N) -> 0
A19: 一级能力域 | B19: 纳入计划项数 | C19: 高优先级 | D19: 已完成 | E19: 备注
A20: P01 Data Infra | B20: =COUNTIFS('02_能力差距自评'!B:B,"P01",'02_能力差距自评'!P:P,"是") -> 0 | C20: =COUNTIFS('02_能力差距自评'!B:B,"P01",'02_能力差距自评'!O:O,"高") -> 0 | D20: =COUNTIFS('02_能力差距自评'!B:B,"P01",'02_能力差距自评'!S:S,"已完成") -> 0
A21: P02 AI Infra / Agent | B21: =COUNTIFS('02_能力差距自评'!B:B,"P02",'02_能力差距自评'!P:P,"是") -> 0 | C21: =COUNTIFS('02_能力差距自评'!B:B,"P02",'02_能力差距自评'!O:O,"高") -> 0 | D21: =COUNTIFS('02_能力差距自评'!B:B,"P02",'02_能力差距自评'!S:S,"已完成") -> 0
A22: P03 Coding | B22: =COUNTIFS('02_能力差距自评'!B:B,"P03",'02_能力差距自评'!P:P,"是") -> 0 | C22: =COUNTIFS('02_能力差距自评'!B:B,"P03",'02_能力差距自评'!O:O,"高") -> 0 | D22: =COUNTIFS('02_能力差距自评'!B:B,"P03",'02_能力差距自评'!S:S,"已完成") -> 0
A23: C01 基本办公 | B23: =COUNTIFS('02_能力差距自评'!B:B,"C01",'02_能力差距自评'!P:P,"是") -> 0 | C23: =COUNTIFS('02_能力差距自评'!B:B,"C01",'02_能力差距自评'!O:O,"高") -> 0 | D23: =COUNTIFS('02_能力差距自评'!B:B,"C01",'02_能力差距自评'!S:S,"已完成") -> 0
A24: C02 沟通协作 | B24: =COUNTIFS('02_能力差距自评'!B:B,"C02",'02_能力差距自评'!P:P,"是") -> 0 | C24: =COUNTIFS('02_能力差距自评'!B:B,"C02",'02_能力差距自评'!O:O,"高") -> 0 | D24: =COUNTIFS('02_能力差距自评'!B:B,"C02",'02_能力差距自评'!S:S,"已完成") -> 0
A25: C03 学习创新 | B25: =COUNTIFS('02_能力差距自评'!B:B,"C03",'02_能力差距自评'!P:P,"是") -> 0 | C25: =COUNTIFS('02_能力差距自评'!B:B,"C03",'02_能力差距自评'!O:O,"高") -> 0 | D25: =COUNTIFS('02_能力差距自评'!B:B,"C03",'02_能力差距自评'!S:S,"已完成") -> 0

Sheet 02_能力差距自评
A1: 能力类别 | B1: 一级序号 | C1: 一级能力域 | D1: 二级序号 | E1: 二级能力项 | F1: 三级序号 | G1: 三级能力项 | H1: 建议起始职级 | I1: 学习材料 | J1: 预期输出 / 验收方式 | K1: 预计耗时(h) | L1: 当前掌握度(0-5) | M1: 目标掌握度(0-5) | N1: 差距 | O1: 优先级 | P1: 是否纳入计划 | Q1: 计划季度 | R1: 计划完成月份 | S1: 完成状态 | T1: 实际输出链接/说明 | U1: 备注 | V1: 推荐行动 | W1: 入选顺序(自动)
A2: 专业能力 | B2: P01 | C2: Data Infra 能力 | D2: P01.01 | E2: Data Infra 产品体系认知 | F2: P01.01.01 | G2: TDC / TDH / ArgoDB / TDS 产品定位 | H2: P4 | I2: P01-M001 | J2: 在测试环境分别访问 TDC、TDH、ArgoDB、TDS，识别产品入口、核心菜单、核心组件；提交产品访问截图、四个产品一句话定位和产品体系脑图。 | K2: 4–6 | N2: =IF(OR(L2="",M2=""),"",MAX(0,M2-L2)) | S2: 未开始 | V2: =IF(N2="","",IF(N2>=3,"年度重点专项",IF(N2=2,"季度重点补齐",IF(N2=1,"月度常规提升","保持观察/可做分享")))) | W2: =IF($P2="是",COUNTIF($P$2:$P2,"是"),"")
A3: 专业能力 | B3: P01 | C3: Data Infra 能力 | D3: P01.01 | E3: Data Infra 产品体系认知 | F3: P01.01.02 | G3: 产品边界与核心能力识别 | H3: P4 | I3: P01-M001 | J3: 基于真实或模拟环境梳理各产品核心能力边界；提交“产品-能力-场景”映射表，至少覆盖数据开发、治理、数据库、平台纳管、湖仓场景。 | K3: 4–8 | N3: =IF(OR(L3="",M3=""),"",MAX(0,M3-L3)) | S3: 未开始 | V3: =IF(N3="","",IF(N3>=3,"年度重点专项",IF(N3=2,"季度重点补齐",IF(N3=1,"月度常规提升","保持观察/可做分享")))) | W3: =IF($P3="是",COUNTIF($P$2:$P3,"是"),"")
A4: 专业能力 | B4: P01 | C4: Data Infra 能力 | D4: P01.01 | E4: Data Infra 产品体系认知 | F4: P01.01.03 | G4: 产品组合关系理解 | H4: P5 | I4: P01-M001、P01-M007 | J4: 基于一套测试部署环境绘制 TDC + TDH + ArgoDB + TDS 组合拓扑图，标注访问入口、依赖关系、数据流向和典型调用关系。 | K4: 6–10 | N4: =IF(OR(L4="",M4=""),"",MAX(0,M4-L4)) | S4: 未开始 | V4: =IF(N4="","",IF(N4>=3,"年度重点专项",IF(N4=2,"季度重点补齐",IF(N4=1,"月度常规提升","保持观察/可做分享")))) | W4: =IF($P4="是",COUNTIF($P$2:$P4,"是"),"")
A5: 专业能力 | B5: P01 | C5: Data Infra 能力 | D5: P01.01 | E5: Data Infra 产品体系认知 | F5: P01.01.04 | G5: 客户场景与产品适配判断 | H5: P6 | I5: P01-M001 | J5: 选择一个典型客户场景，输出产品组合建议、适用边界、不适用边界和风险点；可附最小验证 Demo 或客户案例说明。 | K5: 8–12 | N5: =IF(OR(L5="",M5=""),"",MAX(0,M5-L5)) | S5: 未开始 | V5: =IF(N5="","",IF(N5>=3,"年度重点专项",IF(N5=2,"季度重点补齐",IF(N5=1,"月度常规提升","保持观察/可做分享")))) | W5: =IF($P5="是",COUNTIF($P$2:$P5,"是"),"")
A6: 专业能力 | B6: P01 | C6: Data Infra 能力 | D6: P01.01 | E6: Data Infra 产品体系认知 | F6: P01.01.05 | G6: 产品体系方法论沉淀 | H6: P8 | I6: P01-M001、P01-M011 | J6: 汇总多个项目或 Demo 经验，沉淀 Data Infra 产品选型标准、培训课件、方案模板和评审检查清单。 | K6: 16–24 | N6: =IF(OR(L6="",M6=""),"",MAX(0,M6-L6)) | S6: 未开始 | U6: 偏 P8 体系化输出 | V6: =IF(N6="","",IF(N6>=3,"年度重点专项",IF(N6=2,"季度重点补齐",IF(N6=1,"月度常规提升","保持观察/可做分享")))) | W6: =IF($P6="是",COUNTIF($P$2:$P6,"是"),"")
A7: 专业能力 | B7: P01 | C7: Data Infra 能力 | D7: P01.02 | E7: TDH 平台与大数据组件能力 | F7: P01.02.01 | G7: TDH 环境检查与安装准备 | H7: P4 | I7: P01-M002 | J7: 在独立服务器或测试集群完成 OS、磁盘、IP、主机名、端口、安装包、时间同步检查；提交环境检查表、问题整改记录和安装前确认清单。 | K7: 6–10 | N7: =IF(OR(L7="",M7=""),"",MAX(0,M7-L7)) | S7: 未开始 | V7: =IF(N7="","",IF(N7>=3,"年度重点专项",IF(N7=2,"季度重点补齐",IF(N7=1,"月度常规提升","保持观察/可做分享")))) | W7: =IF($P7="是",COUNTIF($P$2:$P7,"是"),"")
A8: 专业能力 | B8: P01 | C8: Data Infra 能力 | D8: P01.02 | E8: TDH 平台与大数据组件能力 | F8: P01.02.02 | G8: TDH 标准部署与基础配置 | H8: P4 | I8: P01-M002 | J8: 在客户正式环境或等价测试环境完成 TDH 标准部署、基础配置和服务启动；提交部署记录、部署截图、基础配置说明和问题清单。 | K8: 24–40 | N8: =IF(OR(L8="",M8=""),"",MAX(0,M8-L8)) | S8: 未开始 | U8: P4 核心验收项 | V8: =IF(N8="","",IF(N8>=3,"年度重点专项",IF(N8=2,"季度重点补齐",IF(N8=1,"月度常规提升","保持观察/可做分享")))) | W8: =IF($P8="是",COUNTIF($P$2:$P8,"是"),"")
A9: 专业能力 | B9: P01 | C9: Data Infra 能力 | D9: P01.02 | E9: TDH 平台与大数据组件能力 | F9: P01.02.03 | G9: TDH Manager 使用与集群管理 | H9: P4 | I9: P01-M002 | J9: 完成 Manager 登录、服务状态查看、服务启停、配置变更、告警查看和基础操作；提交操作截图、状态截图和操作说明。 | K9: 6–10 | N9: =IF(OR(L9="",M9=""),"",MAX(0,M9-L9)) | S9: 未开始 | V9: =IF(N9="","",IF(N9>=3,"年度重点专项",IF(N9=2,"季度重点补齐",IF(N9=1,"月度常规提升","保持观察/可做分享")))) | W9: =IF($P9="是",COUNTIF($P$2:$P9,"是"),"")
A10: 专业能力 | B10: P01 | C10: Data Infra 能力 | D10: P01.02 | E10: TDH 平台与大数据组件能力 | F10: P01.02.04 | G10: HDFS / YARN / ZK / Kafka 基础组件认知与验证 | H10: P4 | I10: P01-M002 | J10: 在 TDH 环境完成 HDFS 文件上传 / 查看、YARN 任务或队列查看、ZK / Kafka 服务状态检查；提交组件验证截图和组件作用说明。 | K10: 8–12 | N10: =IF(OR(L10="",M10=""),"",MAX(0,M10-L10)) | S10: 未开始 | V10: =IF(N10="","",IF(N10>=3,"年度重点专项",IF(N10=2,"季度重点补齐",IF(N10=1,"月度常规提升","保持观察/可做分享")))) | W10: =IF($P10="是",COUNTIF($P$2:$P10,"是"),"")
A11: 专业能力 | B11: P01 | C11: Data Infra 能力 | D11: P01.02 | E11: TDH 平台与大数据组件能力 | F11: P01.02.05 | G11: Inceptor / Hyperbase / Scope / Slipstream 等组件认知与验证 | H11: P4–P5 | I11: P01-M002 | J11: 至少选择 2 个组件完成启动状态检查、连接访问或基础查询 / 任务验证；提交组件能力对照表、验证截图和场景说明。 | K11: 10–16 | N11: =IF(OR(L11="",M11=""),"",MAX(0,M11-L11)) | S11: 未开始 | V11: =IF(N11="","",IF(N11>=3,"年度重点专项",IF(N11=2,"季度重点补齐",IF(N11=1,"月度常规提升","保持观察/可做分享")))) | W11: =IF($P11="是",COUNTIF($P$2:$P11,"是"),"")
A12: 专业能力 | B12: P01 | C12: Data Infra 能力 | D12: P01.02 | E12: TDH 平台与大数据组件能力 | F12: P01.02.06 | G12: TDH 组件验证与常见问题排查 | H12: P5 | I12: P01-M002 | J12: 基于部署或运维过程处理至少 2 类常见问题，如服务异常、配置错误、资源不足、连接失败；提交问题现象、日志定位、处理步骤和恢复结果。 | K12: 12–20 | N12: =IF(OR(L12="",M12=""),"",MAX(0,M12-L12)) | S12: 未开始 | V12: =IF(N12="","",IF(N12>=3,"年度重点专项",IF(N12=2,"季度重点补齐",IF(N12=1,"月度常规提升","保持观察/可做分享")))) | W12: =IF($P12="是",COUNTIF($P$2:$P12,"是"),"")
A13: 专业能力 | B13: P01 | C13: Data Infra 能力 | D13: P01.02 | E13: TDH 平台与大数据组件能力 | F13: P01.02.07 | G13: TDH 角色规划、磁盘规划、资源规划 | H13: P6 | I13: P01-M002、P01-M009 | J13: 基于给定服务器清单设计 TDH 角色规划、磁盘分区、资源分配和部署规划；提交规划表、架构图和设计理由。 | K13: 16–24 | N13: =IF(OR(L13="",M13=""),"",MAX(0,M13-L13)) | S13: 未开始 | V13: =IF(N13="","",IF(N13>=3,"年度重点专项",IF(N13=2,"季度重点补齐",IF(N13=1,"月度常规提升","保持观察/可做分享")))) | W13: =IF($P13="是",COUNTIF($P$2:$P13,"是"),"")
A14: 专业能力 | B14: P01 | C14: Data Infra 能力 | D14: P01.02 | E14: TDH 平台与大数据组件能力 | F14: P01.02.08 | G14: TDH 部署规范与最佳实践沉淀 | H14: P7–P8 | I14: P01-M002、P01-M011 | J14: 基于多次部署经验沉淀 TDH 部署规范、检查清单、巡检标准、常见问题库和培训材料。 | K14: 16–32 | N14: =IF(OR(L14="",M14=""),"",MAX(0,M14-L14)) | S14: 未开始 | V14: =IF(N14="","",IF(N14>=3,"年度重点专项",IF(N14=2,"季度重点补齐",IF(N14=1,"月度常规提升","保持观察/可做分享")))) | W14: =IF($P14="是",COUNTIF($P$2:$P14,"是"),"")
A15: 专业能力 | B15: P01 | C15: Data Infra 能力 | D15: P01.03 | E15: TDC 多租户数据平台能力 | F15: P01.03.01 | G15: TDC 基础概念：租户、用户、Namespace、系统服务 | H15: P4 | I15: P01-M003 | J15: 在 TDC 环境中识别租户、用户、Namespace、系统服务、产品实例等对象；提交概念关系图、页面截图和对象说明。 | K15: 4–8 | N15: =IF(OR(L15="",M15=""),"",MAX(0,M15-L15)) | S15: 未开始 | V15: =IF(N15="","",IF(N15>=3,"年度重点专项",IF(N15=2,"季度重点补齐",IF(N15=1,"月度常规提升","保持观察/可做分享")))) | W15: =IF($P15="是",COUNTIF($P$2:$P15,"是"),"")
A16: 专业能力 | B16: P01 | C16: Data Infra 能力 | D16: P01.03 | E16: TDC 多租户数据平台能力 | F16: P01.03.02 | G16: TDC 标准部署与基础验证 | H16: P4 | I16: P01-M003 | J16: 在独立服务器或测试集群完成 TDC 标准部署和基础验证；提交部署记录、基础服务状态截图、验证清单和问题记录。 | K16: 24–40 | N16: =IF(OR(L16="",M16=""),"",MAX(0,M16-L16)) | S16: 未开始 | U16: P4 核心验收项 | V16: =IF(N16="","",IF(N16>=3,"年度重点专项",IF(N16=2,"季度重点补齐",IF(N16=1,"月度常规提升","保持观察/可做分享")))) | W16: =IF($P16="是",COUNTIF($P$2:$P16,"是"),"")
A17: 专业能力 | B17: P01 | C17: Data Infra 能力 | D17: P01.03 | E17: TDC 多租户数据平台能力 | F17: P01.03.03 | G17: 租户创建、租户用户、权限基础配置 | H17: P4 | I17: P01-M003、P01-M010 | J17: 完成租户创建、用户加入、基础角色和权限配置，并验证租户内访问；提交配置截图、权限验证记录和操作说明。 | K17: 8–12 | N17: =IF(OR(L17="",M17=""),"",MAX(0,M17-L17)) | S17: 未开始 | V17: =IF(N17="","",IF(N17>=3,"年度重点专项",IF(N17=2,"季度重点补齐",IF(N17=1,"月度常规提升","保持观察/可做分享")))) | W17: =IF($P17="是",COUNTIF($P$2:$P17,"是"),"")
A18: 专业能力 | B18: P01 | C18: Data Infra 能力 | D18: P01.03 | E18: TDC 多租户数据平台能力 | F18: P01.03.04 | G18: 产品纳管与云产品实例配置 | H18: P4 | I18: P01-M003 | J18: 完成至少一个产品纳管或实例配置验证，如 TDH / ArgoDB / TDS 纳管；提交纳管截图、实例状态截图和访问验证记录。 | K18: 8–16 | N18: =IF(OR(L18="",M18=""),"",MAX(0,M18-L18)) | S18: 未开始 | V18: =IF(N18="","",IF(N18>=3,"年度重点专项",IF(N18=2,"季度重点补齐",IF(N18=1,"月度常规提升","保持观察/可做分享")))) | W18: =IF($P18="是",COUNTIF($P$2:$P18,"是"),"")
A19: 专业能力 | B19: P01 | C19: Data Infra 能力 | D19: P01.03 | E19: TDC 多租户数据平台能力 | F19: P01.03.05 | G19: K8s / Container / Helm Chart 基础认知与排查 | H19: P4–P5 | I19: P01-M003 | J19: 查看 Namespace、Pod、Service、Container 等资源状态，完成一次基础问题定位或状态解释；提交命令输出、截图和排查说明。 | K19: 8–12 | N19: =IF(OR(L19="",M19=""),"",MAX(0,M19-L19)) | S19: 未开始 | V19: =IF(N19="","",IF(N19>=3,"年度重点专项",IF(N19=2,"季度重点补齐",IF(N19=1,"月度常规提升","保持观察/可做分享")))) | W19: =IF($P19="是",COUNTIF($P$2:$P19,"是"),"")
A20: 专业能力 | B20: P01 | C20: Data Infra 能力 | D20: P01.03 | E20: TDC 多租户数据平台能力 | F20: P01.03.06 | G20: TDC Client 使用与租户内产品访问 | H20: P4–P5 | I20: P01-M003 | J20: 完成 TDC Client 初始化、环境变量配置和租户内产品访问验证；提交配置记录、连接截图和访问结果。 | K20: 6–10 | N20: =IF(OR(L20="",M20=""),"",MAX(0,M20-L20)) | S20: 未开始 | V20: =IF(N20="","",IF(N20>=3,"年度重点专项",IF(N20=2,"季度重点补齐",IF(N20=1,"月度常规提升","保持观察/可做分享")))) | W20: =IF($P20="是",COUNTIF($P$2:$P20,"是"),"")
A21: 专业能力 | B21: P01 | C21: Data Infra 能力 | D21: P01.03 | E21: TDC 多租户数据平台能力 | F21: P01.03.07 | G21: 资源隔离、共享租户、数据共享设计 | H21: P6 | I21: P01-M003、P01-M007、P01-M010 | J21: 基于总部 / 事业部或多部门场景设计租户资源隔离、共享租户和数据共享方案；提交方案图、权限矩阵和验证思路。 | K21: 16–24 | N21: =IF(OR(L21="",M21=""),"",MAX(0,M21-L21)) | S21: 未开始 | V21: =IF(N21="","",IF(N21>=3,"年度重点专项",IF(N21=2,"季度重点补齐",IF(N21=1,"月度常规提升","保持观察/可做分享")))) | W21: =IF($P21="是",COUNTIF($P$2:$P21,"是"),"")
A22: 专业能力 | B22: P01 | C22: Data Infra 能力 | D22: P01.03 | E22: TDC 多租户数据平台能力 | F22: P01.03.08 | G22: 应用上架、应用生命周期、平台治理 | H22: P6–P7 | I22: P01-M003 | J22: 完成一个应用或组件上架、启动、访问和下线流程，或输出应用上架流程方案；提交 Demo 记录、生命周期说明和风险点。 | K22: 16–24 | N22: =IF(OR(L22="",M22=""),"",MAX(0,M22-L22)) | S22: 未开始 | V22: =IF(N22="","",IF(N22>=3,"年度重点专项",IF(N22=2,"季度重点补齐",IF(N22=1,"月度常规提升","保持观察/可做分享")))) | W22: =IF($P22="是",COUNTIF($P$2:$P22,"是"),"")
A23: 专业能力 | B23: P01 | C23: Data Infra 能力 | D23: P01.03 | E23: TDC 多租户数据平台能力 | F23: P01.03.09 | G23: TDC 多租户平台方法论沉淀 | H23: P8 | I23: P01-M003、P01-M011 | J23: 沉淀 TDC 多租户平台建设方法论、租户规划模板、资源隔离最佳实践和标准交付清单。 | K23: 16–32 | N23: =IF(OR(L23="",M23=""),"",MAX(0,M23-L23)) | S23: 未开始 | V23: =IF(N23="","",IF(N23>=3,"年度重点专项",IF(N23=2,"季度重点补齐",IF(N23=1,"月度常规提升","保持观察/可做分享")))) | W23: =IF($P23="是",COUNTIF($P$2:$P23,"是"),"")
A24: 专业能力 | B24: P01 | C24: Data Infra 能力 | D24: P01.04 | E24: ArgoDB 使用与优化能力 | F24: P01.04.01 | G24: ArgoDB 安装、连接、基础架构认知 | H24: P4 | I24: P01-M004 | J24: 完成 ArgoDB 安装、客户端连接和基础架构识别；提交安装连接记录、服务状态截图和架构说明。 | K24: 8–12 | N24: =IF(OR(L24="",M24=""),"",MAX(0,M24-L24)) | S24: 未开始 | V24: =IF(N24="","",IF(N24>=3,"年度重点专项",IF(N24=2,"季度重点补齐",IF(N24=1,"月度常规提升","保持观察/可做分享")))) | W24: =IF($P24="是",COUNTIF($P$2:$P24,"是"),"")
A25: 专业能力 | B25: P01 | C25: Data Infra 能力 | D25: P01.04 | E25: ArgoDB 使用与优化能力 | F25: P01.04.02 | G25: 建库、建表、基础 SQL 查询 | H25: P4 | I25: P01-M004 | J25: 创建数据库、普通表并完成基础查询、聚合查询和简单关联查询；提交 SQL 脚本、执行截图和结果说明。 | K25: 6–10 | N25: =IF(OR(L25="",M25=""),"",MAX(0,M25-L25)) | S25: 未开始 | V25: =IF(N25="","",IF(N25>=3,"年度重点专项",IF(N25=2,"季度重点补齐",IF(N25=1,"月度常规提升","保持观察/可做分享")))) | W25: =IF($P25="是",COUNTIF($P$2:$P25,"是"),"")
A26: 专业能力 | B26: P01 | C26: Data Infra 能力 | D26: P01.04 | E26: ArgoDB 使用与优化能力 | F26: P01.04.03 | G26: 分区、分桶、表数据组织 | H26: P4 | I26: P01-M004 | J26: 创建分区表、分桶表并导入测试数据，验证分区 / 分桶查询效果；提交 DDL、SQL、执行截图和设计说明。 | K26: 8–12 | N26: =IF(OR(L26="",M26=""),"",MAX(0,M26-L26)) | S26: 未开始 | U26: P4 重点 | V26: =IF(N26="","",IF(N26>=3,"年度重点专项",IF(N26=2,"季度重点补齐",IF(N26=1,"月度常规提升","保持观察/可做分享")))) | W26: =IF($P26="是",COUNTIF($P$2:$P26,"是"),"")
A27: 专业能力 | B27: P01 | C27: Data Infra 能力 | D27: P01.04 | E27: ArgoDB 使用与优化能力 | F27: P01.04.04 | G27: 批量写入与数据导入 | H27: P4 | I27: P01-M004 | J27: 完成批量数据写入或导入，并验证数据量、字段和值正确；提交导入脚本、校验 SQL 和结果截图。 | K27: 6–10 | N27: =IF(OR(L27="",M27=""),"",MAX(0,M27-L27)) | S27: 未开始 | V27: =IF(N27="","",IF(N27>=3,"年度重点专项",IF(N27=2,"季度重点补齐",IF(N27=1,"月度常规提升","保持观察/可做分享")))) | W27: =IF($P27="是",COUNTIF($P$2:$P27,"是"),"")
A28: 专业能力 | B28: P01 | C28: Data Infra 能力 | D28: P01.04 | E28: ArgoDB 使用与优化能力 | F28: P01.04.05 | G28: 实时写入、更新、MERGE INTO | H28: P5 | I28: P01-M004 | J28: 完成实时写入、更新和 MERGE INTO 示例，并验证写入结果和变更结果；提交 SQL 脚本、执行记录和结果说明。 | K28: 10–16 | N28: =IF(OR(L28="",M28=""),"",MAX(0,M28-L28)) | S28: 未开始 | V28: =IF(N28="","",IF(N28>=3,"年度重点专项",IF(N28=2,"季度重点补齐",IF(N28=1,"月度常规提升","保持观察/可做分享")))) | W28: =IF($P28="是",COUNTIF($P$2:$P28,"是"),"")
A29: 专业能力 | B29: P01 | C29: Data Infra 能力 | D29: P01.04 | E29: ArgoDB 使用与优化能力 | F29: P01.04.06 | G29: 基础 SQL 优化与执行问题排查 | H29: P4–P5 | I29: P01-M004 | J29: 选取一个低效 SQL，完成优化前后对比，或处理一次 SQL 执行异常；提交执行计划、耗时对比和排查记录。 | K29: 8–16 | N29: =IF(OR(L29="",M29=""),"",MAX(0,M29-L29)) | S29: 未开始 | U29: 分 P4 基础优化、P5 常见问题 | V29: =IF(N29="","",IF(N29>=3,"年度重点专项",IF(N29=2,"季度重点补齐",IF(N29=1,"月度常规提升","保持观察/可做分享")))) | W29: =IF($P29="是",COUNTIF($P$2:$P29,"是"),"")
A30: 专业能力 | B30: P01 | C30: Data Infra 能力 | D30: P01.04 | E30: ArgoDB 使用与优化能力 | F30: P01.04.07 | G30: 表设计、数据模型设计与资源配置 | H30: P6 | I30: P01-M004、P01-M007 | J30: 针对一个分析场景设计表结构、分区分桶策略、数据组织和资源配置建议；提交设计文档、DDL 和验证 SQL。 | K30: 16–24 | N30: =IF(OR(L30="",M30=""),"",MAX(0,M30-L30)) | S30: 未开始 | V30: =IF(N30="","",IF(N30>=3,"年度重点专项",IF(N30=2,"季度重点补齐",IF(N30=1,"月度常规提升","保持观察/可做分享")))) | W30: =IF($P30="是",COUNTIF($P$2:$P30,"是"),"")
A31: 专业能力 | B31: P01 | C31: Data Infra 能力 | D31: P01.04 | E31: ArgoDB 使用与优化能力 | F31: P01.04.08 | G31: 实时湖仓 / OLAP / 高并发场景设计 | H31: P7 | I31: P01-M004、P01-M007、P01-M009 | J31: 基于湖仓或高并发查询场景设计 ArgoDB 架构和性能验证方案；提交架构图、压测方案、验收指标和风险点。 | K31: 24–40 | N31: =IF(OR(L31="",M31=""),"",MAX(0,M31-L31)) | S31: 未开始 | V31: =IF(N31="","",IF(N31>=3,"年度重点专项",IF(N31=2,"季度重点补齐",IF(N31=1,"月度常规提升","保持观察/可做分享")))) | W31: =IF($P31="是",COUNTIF($P$2:$P31,"是"),"")
A32: 专业能力 | B32: P01 | C32: Data Infra 能力 | D32: P01.04 | E32: ArgoDB 使用与优化能力 | F32: P01.04.09 | G32: ArgoDB 最佳实践沉淀 | H32: P8 | I32: P01-M004、P01-M011 | J32: 沉淀 ArgoDB 建模规范、选型标准、性能基线、SQL 调优方法和复杂问题处理手册。 | K32: 16–32 | N32: =IF(OR(L32="",M32=""),"",MAX(0,M32-L32)) | S32: 未开始 | V32: =IF(N32="","",IF(N32>=3,"年度重点专项",IF(N32=2,"季度重点补齐",IF(N32=1,"月度常规提升","保持观察/可做分享")))) | W32: =IF($P32="是",COUNTIF($P$2:$P32,"是"),"")
A33: 专业能力 | B33: P01 | C33: Data Infra 能力 | D33: P01.05 | E33: TDS 数据开发能力 | F33: P01.05.01 | G33: TDS 数据开发套件认知 | H33: P4 | I33: P01-M005 | J33: 在 TDS 环境中识别 Workflow、Transporter、SQLBook、脱敏等开发能力入口；提交功能入口截图和开发套件能力清单。 | K33: 4–8 | N33: =IF(OR(L33="",M33=""),"",MAX(0,M33-L33)) | S33: 未开始 | V33: =IF(N33="","",IF(N33>=3,"年度重点专项",IF(N33=2,"季度重点补齐",IF(N33=1,"月度常规提升","保持观察/可做分享")))) | W33: =IF($P33="是",COUNTIF($P$2:$P33,"是"),"")
A34: 专业能力 | B34: P01 | C34: Data Infra 能力 | D34: P01.05 | E34: TDS 数据开发能力 | F34: P01.05.02 | G34: 数据源配置与数据同步 | H34: P4 | I34: P01-M005、P01-M008 | J34: 配置源端与目标端数据源，完成一条数据同步任务并校验结果；提交配置截图、同步结果和数据校验 SQL。 | K34: 8–16 | N34: =IF(OR(L34="",M34=""),"",MAX(0,M34-L34)) | S34: 未开始 | U34: P4 重点 | V34: =IF(N34="","",IF(N34>=3,"年度重点专项",IF(N34=2,"季度重点补齐",IF(N34=1,"月度常规提升","保持观察/可做分享")))) | W34: =IF($P34="是",COUNTIF($P$2:$P34,"是"),"")
A35: 专业能力 | B35: P01 | C35: Data Infra 能力 | D35: P01.05 | E35: TDS 数据开发能力 | F35: P01.05.03 | G35: SQLBook 使用与 SQL 分析 | H35: P4 | I35: P01-M005 | J35: 使用 SQLBook 完成至少 3 个查询分析场景，包括查询、聚合、结果查看；提交 SQL、执行结果截图和分析说明。 | K35: 6–10 | N35: =IF(OR(L35="",M35=""),"",MAX(0,M35-L35)) | S35: 未开始 | V35: =IF(N35="","",IF(N35>=3,"年度重点专项",IF(N35=2,"季度重点补齐",IF(N35=1,"月度常规提升","保持观察/可做分享")))) | W35: =IF($P35="是",COUNTIF($P$2:$P35,"是"),"")
A36: 专业能力 | B36: P01 | C36: Data Infra 能力 | D36: P01.05 | E36: TDS 数据开发能力 | F36: P01.05.04 | G36: Workflow 任务流与调度配置 | H36: P4 | I36: P01-M005 | J36: 配置包含依赖关系的任务流和调度周期，完成运行验证；提交任务流截图、调度配置和运行结果。 | K36: 8–12 | N36: =IF(OR(L36="",M36=""),"",MAX(0,M36-L36)) | S36: 未开始 | V36: =IF(N36="","",IF(N36>=3,"年度重点专项",IF(N36=2,"季度重点补齐",IF(N36=1,"月度常规提升","保持观察/可做分享")))) | W36: =IF($P36="是",COUNTIF($P$2:$P36,"是"),"")
A37: 专业能力 | B37: P01 | C37: Data Infra 能力 | D37: P01.05 | E37: TDS 数据开发能力 | F37: P01.05.05 | G37: Transporter 数据传输任务 | H37: P4 | I37: P01-M005、P01-M008 | J37: 完成一次 Transporter 数据传输任务，并验证源端 / 目标端数据一致；提交任务配置截图、校验 SQL 和验证结果。 | K37: 8–12 | N37: =IF(OR(L37="",M37=""),"",MAX(0,M37-L37)) | S37: 未开始 | V37: =IF(N37="","",IF(N37>=3,"年度重点专项",IF(N37=2,"季度重点补齐",IF(N37=1,"月度常规提升","保持观察/可做分享")))) | W37: =IF($P37="是",COUNTIF($P$2:$P37,"是"),"")
A38: 专业能力 | B38: P01 | C38: Data Infra 能力 | D38: P01.05 | E38: TDS 数据开发能力 | F38: P01.05.06 | G38: 静态脱敏、策略脱敏、基础数据安全处理 | H38: P4 | I38: P01-M005、P01-M010 | J38: 配置静态脱敏或策略脱敏任务，并验证脱敏前后数据效果；提交配置截图、脱敏前后对比和说明。 | K38: 8–12 | N38: =IF(OR(L38="",M38=""),"",MAX(0,M38-L38)) | S38: 未开始 | V38: =IF(N38="","",IF(N38>=3,"年度重点专项",IF(N38=2,"季度重点补齐",IF(N38=1,"月度常规提升","保持观察/可做分享")))) | W38: =IF($P38="是",COUNTIF($P$2:$P38,"是"),"")
A39: 专业能力 | B39: P01 | C39: Data Infra 能力 | D39: P01.05 | E39: TDS 数据开发能力 | F39: P01.05.07 | G39: 任务依赖、异常重跑、任务运维 | H39: P5 | I39: P01-M005 | J39: 模拟或处理一次任务失败，完成定位、重跑和恢复；提交异常截图、处理步骤、重跑结果和复盘记录。 | K39: 8–16 | N39: =IF(OR(L39="",M39=""),"",MAX(0,M39-L39)) | S39: 未开始 | V39: =IF(N39="","",IF(N39>=3,"年度重点专项",IF(N39=2,"季度重点补齐",IF(N39=1,"月度常规提升","保持观察/可做分享")))) | W39: =IF($P39="是",COUNTIF($P$2:$P39,"是"),"")
A40: 专业能力 | B40: P01 | C40: Data Infra 能力 | D40: P01.05 | E40: TDS 数据开发能力 | F40: P01.05.08 | G40: 数据开发流程与开发规范设计 | H40: P6–P7 | I40: P01-M005、P01-M011 | J40: 基于数仓 / 湖仓项目设计数据开发流程、任务命名规范、依赖规范、异常处理规范和交付模板。 | K40: 16–32 | N40: =IF(OR(L40="",M40=""),"",MAX(0,M40-L40)) | S40: 未开始 | V40: =IF(N40="","",IF(N40>=3,"年度重点专项",IF(N40=2,"季度重点补齐",IF(N40=1,"月度常规提升","保持观察/可做分享")))) | W40: =IF($P40="是",COUNTIF($P$2:$P40,"是"),"")
...

Sheet 03_年度学习计划
A1: 计划编号 | B1: 季度 | C1: 月份 | D1: 能力编码 | E1: 三级能力项 | F1: 一级能力域 | G1: 二级能力项 | H1: 当前掌握度 | I1: 目标掌握度 | J1: 差距 | K1: 优先级 | L1: 学习材料 | M1: 学习任务 / 实操内容 | N1: 预期输出 / 验收方式 | O1: 预计耗时(h) | P1: 计划开始 | Q1: 计划截止 | R1: 实际耗时(h) | S1: 状态 | T1: 证据链接 / 文件 | U1: 复盘结论 | V1: 备注
A2: =IF($D2="","","LP"&TEXT(ROWS($A$2:A2),"000")) | B2: =IF($D2="","",IFERROR(INDEX('02_能力差距自评'!$Q:$Q,MATCH($D2,'02_能力差距自评'!$F:$F,0)),"")) | C2: =IF($D2="","",IFERROR(INDEX('02_能力差距自评'!$R:$R,MATCH($D2,'02_能力差距自评'!$F:$F,0)),"")) | D2: =IFERROR(INDEX('02_能力差距自评'!$F$2:$F$311,MATCH(ROWS($D$2:D2),'02_能力差距自评'!$W$2:$W$311,0)),"") | E2: =IF($D2="","",INDEX('02_能力差距自评'!$G:$G,MATCH($D2,'02_能力差距自评'!$F:$F,0))) | F2: =IF($D2="","",INDEX('02_能力差距自评'!$C:$C,MATCH($D2,'02_能力差距自评'!$F:$F,0))) | G2: =IF($D2="","",INDEX('02_能力差距自评'!$E:$E,MATCH($D2,'02_能力差距自评'!$F:$F,0))) | H2: =IF($D2="","",INDEX('02_能力差距自评'!$L:$L,MATCH($D2,'02_能力差距自评'!$F:$F,0))) | I2: =IF($D2="","",INDEX('02_能力差距自评'!$M:$M,MATCH($D2,'02_能力差距自评'!$F:$F,0))) | J2: =IF($D2="","",INDEX('02_能力差距自评'!$N:$N,MATCH($D2,'02_能力差距自评'!$F:$F,0))) | K2: =IF($D2="","",INDEX('02_能力差距自评'!$O:$O,MATCH($D2,'02_能力差距自评'!$F:$F,0))) | L2: =IF($D2="","",INDEX('02_能力差距自评'!$I:$I,MATCH($D2,'02_能力差距自评'!$F:$F,0))) | M2: =IF($D2="","",$E2) | N2: =IF($D2="","",INDEX('02_能力差距自评'!$J:$J,MATCH($D2,'02_能力差距自评'!$F:$F,0))) | O2: =IF($D2="","",INDEX('02_能力差距自评'!$K:$K,MATCH($D2,'02_能力差距自评'!$F:$F,0))) | S2: =IF($D2="","","未开始")
A3: =IF($D3="","","LP"&TEXT(ROWS($A$2:A3),"000")) | B3: =IF($D3="","",IFERROR(INDEX('02_能力差距自评'!$Q:$Q,MATCH($D3,'02_能力差距自评'!$F:$F,0)),"")) | C3: =IF($D3="","",IFERROR(INDEX('02_能力差距自评'!$R:$R,MATCH($D3,'02_能力差距自评'!$F:$F,0)),"")) | D3: =IFERROR(INDEX('02_能力差距自评'!$F$2:$F$311,MATCH(ROWS($D$2:D3),'02_能力差距自评'!$W$2:$W$311,0)),"") | E3: =IF($D3="","",INDEX('02_能力差距自评'!$G:$G,MATCH($D3,'02_能力差距自评'!$F:$F,0))) | F3: =IF($D3="","",INDEX('02_能力差距自评'!$C:$C,MATCH($D3,'02_能力差距自评'!$F:$F,0))) | G3: =IF($D3="","",INDEX('02_能力差距自评'!$E:$E,MATCH($D3,'02_能力差距自评'!$F:$F,0))) | H3: =IF($D3="","",INDEX('02_能力差距自评'!$L:$L,MATCH($D3,'02_能力差距自评'!$F:$F,0))) | I3: =IF($D3="","",INDEX('02_能力差距自评'!$M:$M,MATCH($D3,'02_能力差距自评'!$F:$F,0))) | J3: =IF($D3="","",INDEX('02_能力差距自评'!$N:$N,MATCH($D3,'02_能力差距自评'!$F:$F,0))) | K3: =IF($D3="","",INDEX('02_能力差距自评'!$O:$O,MATCH($D3,'02_能力差距自评'!$F:$F,0))) | L3: =IF($D3="","",INDEX('02_能力差距自评'!$I:$I,MATCH($D3,'02_能力差距自评'!$F:$F,0))) | M3: =IF($D3="","",$E3) | N3: =IF($D3="","",INDEX('02_能力差距自评'!$J:$J,MATCH($D3,'02_能力差距自评'!$F:$F,0))) | O3: =IF($D3="","",INDEX('02_能力差距自评'!$K:$K,MATCH($D3,'02_能力差距自评'!$F:$F,0))) | S3: =IF($D3="","","未开始")
A4: =IF($D4="","","LP"&TEXT(ROWS($A$2:A4),"000")) | B4: =IF($D4="","",IFERROR(INDEX('02_能力差距自评'!$Q:$Q,MATCH($D4,'02_能力差距自评'!$F:$F,0)),"")) | C4: =IF($D4="","",IFERROR(INDEX('02_能力差距自评'!$R:$R,MATCH($D4,'02_能力差距自评'!$F:$F,0)),"")) | D4: =IFERROR(INDEX('02_能力差距自评'!$F$2:$F$311,MATCH(ROWS($D$2:D4),'02_能力差距自评'!$W$2:$W$311,0)),"") | E4: =IF($D4="","",INDEX('02_能力差距自评'!$G:$G,MATCH($D4,'02_能力差距自评'!$F:$F,0))) | F4: =IF($D4="","",INDEX('02_能力差距自评'!$C:$C,MATCH($D4,'02_能力差距自评'!$F:$F,0))) | G4: =IF($D4="","",INDEX('02_能力差距自评'!$E:$E,MATCH($D4,'02_能力差距自评'!$F:$F,0))) | H4: =IF($D4="","",INDEX('02_能力差距自评'!$L:$L,MATCH($D4,'02_能力差距自评'!$F:$F,0))) | I4: =IF($D4="","",INDEX('02_能力差距自评'!$M:$M,MATCH($D4,'02_能力差距自评'!$F:$F,0))) | J4: =IF($D4="","",INDEX('02_能力差距自评'!$N:$N,MATCH($D4,'02_能力差距自评'!$F:$F,0))) | K4: =IF($D4="","",INDEX('02_能力差距自评'!$O:$O,MATCH($D4,'02_能力差距自评'!$F:$F,0))) | L4: =IF($D4="","",INDEX('02_能力差距自评'!$I:$I,MATCH($D4,'02_能力差距自评'!$F:$F,0))) | M4: =IF($D4="","",$E4) | N4: =IF($D4="","",INDEX('02_能力差距自评'!$J:$J,MATCH($D4,'02_能力差距自评'!$F:$F,0))) | O4: =IF($D4="","",INDEX('02_能力差距自评'!$K:$K,MATCH($D4,'02_能力差距自评'!$F:$F,0))) | S4: =IF($D4="","","未开始")
A5: =IF($D5="","","LP"&TEXT(ROWS($A$2:A5),"000")) | B5: =IF($D5="","",IFERROR(INDEX('02_能力差距自评'!$Q:$Q,MATCH($D5,'02_能力差距自评'!$F:$F,0)),"")) | C5: =IF($D5="","",IFERROR(INDEX('02_能力差距自评'!$R:$R,MATCH($D5,'02_能力差距自评'!$F:$F,0)),"")) | D5: =IFERROR(INDEX('02_能力差距自评'!$F$2:$F$311,MATCH(ROWS($D$2:D5),'02_能力差距自评'!$W$2:$W$311,0)),"") | E5: =IF($D5="","",INDEX('02_能力差距自评'!$G:$G,MATCH($D5,'02_能力差距自评'!$F:$F,0))) | F5: =IF($D5="","",INDEX('02_能力差距自评'!$C:$C,MATCH($D5,'02_能力差距自评'!$F:$F,0))) | G5: =IF($D5="","",INDEX('02_能力差距自评'!$E:$E,MATCH($D5,'02_能力差距自评'!$F:$F,0))) | H5: =IF($D5="","",INDEX('02_能力差距自评'!$L:$L,MATCH($D5,'02_能力差距自评'!$F:$F,0))) | I5: =IF($D5="","",INDEX('02_能力差距自评'!$M:$M,MATCH($D5,'02_能力差距自评'!$F:$F,0))) | J5: =IF($D5="","",INDEX('02_能力差距自评'!$N:$N,MATCH($D5,'02_能力差距自评'!$F:$F,0))) | K5: =IF($D5="","",INDEX('02_能力差距自评'!$O:$O,MATCH($D5,'02_能力差距自评'!$F:$F,0))) | L5: =IF($D5="","",INDEX('02_能力差距自评'!$I:$I,MATCH($D5,'02_能力差距自评'!$F:$F,0))) | M5: =IF($D5="","",$E5) | N5: =IF($D5="","",INDEX('02_能力差距自评'!$J:$J,MATCH($D5,'02_能力差距自评'!$F:$F,0))) | O5: =IF($D5="","",INDEX('02_能力差距自评'!$K:$K,MATCH($D5,'02_能力差距自评'!$F:$F,0))) | S5: =IF($D5="","","未开始")
A6: =IF($D6="","","LP"&TEXT(ROWS($A$2:A6),"000")) | B6: =IF($D6="","",IFERROR(INDEX('02_能力差距自评'!$Q:$Q,MATCH($D6,'02_能力差距自评'!$F:$F,0)),"")) | C6: =IF($D6="","",IFERROR(INDEX('02_能力差距自评'!$R:$R,MATCH($D6,'02_能力差距自评'!$F:$F,0)),"")) | D6: =IFERROR(INDEX('02_能力差距自评'!$F$2:$F$311,MATCH(ROWS($D$2:D6),'02_能力差距自评'!$W$2:$W$311,0)),"") | E6: =IF($D6="","",INDEX('02_能力差距自评'!$G:$G,MATCH($D6,'02_能力差距自评'!$F:$F,0))) | F6: =IF($D6="","",INDEX('02_能力差距自评'!$C:$C,MATCH($D6,'02_能力差距自评'!$F:$F,0))) | G6: =IF($D6="","",INDEX('02_能力差距自评'!$E:$E,MATCH($D6,'02_能力差距自评'!$F:$F,0))) | H6: =IF($D6="","",INDEX('02_能力差距自评'!$L:$L,MATCH($D6,'02_能力差距自评'!$F:$F,0))) | I6: =IF($D6="","",INDEX('02_能力差距自评'!$M:$M,MATCH($D6,'02_能力差距自评'!$F:$F,0))) | J6: =IF($D6="","",INDEX('02_能力差距自评'!$N:$N,MATCH($D6,'02_能力差距自评'!$F:$F,0))) | K6: =IF($D6="","",INDEX('02_能力差距自评'!$O:$O,MATCH($D6,'02_能力差距自评'!$F:$F,0))) | L6: =IF($D6="","",INDEX('02_能力差距自评'!$I:$I,MATCH($D6,'02_能力差距自评'!$F:$F,0))) | M6: =IF($D6="","",$E6) | N6: =IF($D6="","",INDEX('02_能力差距自评'!$J:$J,MATCH($D6,'02_能力差距自评'!$F:$F,0))) | O6: =IF($D6="","",INDEX('02_能力差距自评'!$K:$K,MATCH($D6,'02_能力差距自评'!$F:$F,0))) | S6: =IF($D6="","","未开始")
A7: =IF($D7="","","LP"&TEXT(ROWS($A$2:A7),"000")) | B7: =IF($D7="","",IFERROR(INDEX('02_能力差距自评'!$Q:$Q,MATCH($D7,'02_能力差距自评'!$F:$F,0)),"")) | C7: =IF($D7="","",IFERROR(INDEX('02_能力差距自评'!$R:$R,MATCH($D7,'02_能力差距自评'!$F:$F,0)),"")) | D7: =IFERROR(INDEX('02_能力差距自评'!$F$2:$F$311,MATCH(ROWS($D$2:D7),'02_能力差距自评'!$W$2:$W$311,0)),"") | E7: =IF($D7="","",INDEX('02_能力差距自评'!$G:$G,MATCH($D7,'02_能力差距自评'!$F:$F,0))) | F7: =IF($D7="","",INDEX('02_能力差距自评'!$C:$C,MATCH($D7,'02_能力差距自评'!$F:$F,0))) | G7: =IF($D7="","",INDEX('02_能力差距自评'!$E:$E,MATCH($D7,'02_能力差距自评'!$F:$F,0))) | H7: =IF($D7="","",INDEX('02_能力差距自评'!$L:$L,MATCH($D7,'02_能力差距自评'!$F:$F,0))) | I7: =IF($D7="","",INDEX('02_能力差距自评'!$M:$M,MATCH($D7,'02_能力差距自评'!$F:$F,0))) | J7: =IF($D7="","",INDEX('02_能力差距自评'!$N:$N,MATCH($D7,'02_能力差距自评'!$F:$F,0))) | K7: =IF($D7="","",INDEX('02_能力差距自评'!$O:$O,MATCH($D7,'02_能力差距自评'!$F:$F,0))) | L7: =IF($D7="","",INDEX('02_能力差距自评'!$I:$I,MATCH($D7,'02_能力差距自评'!$F:$F,0))) | M7: =IF($D7="","",$E7) | N7: =IF($D7="","",INDEX('02_能力差距自评'!$J:$J,MATCH($D7,'02_能力差距自评'!$F:$F,0))) | O7: =IF($D7="","",INDEX('02_能力差距自评'!$K:$K,MATCH($D7,'02_能力差距自评'!$F:$F,0))) | S7: =IF($D7="","","未开始")
A8: =IF($D8="","","LP"&TEXT(ROWS($A$2:A8),"000")) | B8: =IF($D8="","",IFERROR(INDEX('02_能力差距自评'!$Q:$Q,MATCH($D8,'02_能力差距自评'!$F:$F,0)),"")) | C8: =IF($D8="","",IFERROR(INDEX('02_能力差距自评'!$R:$R,MATCH($D8,'02_能力差距自评'!$F:$F,0)),"")) | D8: =IFERROR(INDEX('02_能力差距自评'!$F$2:$F$311,MATCH(ROWS($D$2:D8),'02_能力差距自评'!$W$2:$W$311,0)),"") | E8: =IF($D8="","",INDEX('02_能力差距自评'!$G:$G,MATCH($D8,'02_能力差距自评'!$F:$F,0))) | F8: =IF($D8="","",INDEX('02_能力差距自评'!$C:$C,MATCH($D8,'02_能力差距自评'!$F:$F,0))) | G8: =IF($D8="","",INDEX('02_能力差距自评'!$E:$E,MATCH($D8,'02_能力差距自评'!$F:$F,0))) | H8: =IF($D8="","",INDEX('02_能力差距自评'!$L:$L,MATCH($D8,'02_能力差距自评'!$F:$F,0))) | I8: =IF($D8="","",INDEX('02_能力差距自评'!$M:$M,MATCH($D8,'02_能力差距自评'!$F:$F,0))) | J8: =IF($D8="","",INDEX('02_能力差距自评'!$N:$N,MATCH($D8,'02_能力差距自评'!$F:$F,0))) | K8: =IF($D8="","",INDEX('02_能力差距自评'!$O:$O,MATCH($D8,'02_能力差距自评'!$F:$F,0))) | L8: =IF($D8="","",INDEX('02_能力差距自评'!$I:$I,MATCH($D8,'02_能力差距自评'!$F:$F,0))) | M8: =IF($D8="","",$E8) | N8: =IF($D8="","",INDEX('02_能力差距自评'!$J:$J,MATCH($D8,'02_能力差距自评'!$F:$F,0))) | O8: =IF($D8="","",INDEX('02_能力差距自评'!$K:$K,MATCH($D8,'02_能力差距自评'!$F:$F,0))) | S8: =IF($D8="","","未开始")
A9: =IF($D9="","","LP"&TEXT(ROWS($A$2:A9),"000")) | B9: =IF($D9="","",IFERROR(INDEX('02_能力差距自评'!$Q:$Q,MATCH($D9,'02_能力差距自评'!$F:$F,0)),"")) | C9: =IF($D9="","",IFERROR(INDEX('02_能力差距自评'!$R:$R,MATCH($D9,'02_能力差距自评'!$F:$F,0)),"")) | D9: =IFERROR(INDEX('02_能力差距自评'!$F$2:$F$311,MATCH(ROWS($D$2:D9),'02_能力差距自评'!$W$2:$W$311,0)),"") | E9: =IF($D9="","",INDEX('02_能力差距自评'!$G:$G,MATCH($D9,'02_能力差距自评'!$F:$F,0))) | F9: =IF($D9="","",INDEX('02_能力差距自评'!$C:$C,MATCH($D9,'02_能力差距自评'!$F:$F,0))) | G9: =IF($D9="","",INDEX('02_能力差距自评'!$E:$E,MATCH($D9,'02_能力差距自评'!$F:$F,0))) | H9: =IF($D9="","",INDEX('02_能力差距自评'!$L:$L,MATCH($D9,'02_能力差距自评'!$F:$F,0))) | I9: =IF($D9="","",INDEX('02_能力差距自评'!$M:$M,MATCH($D9,'02_能力差距自评'!$F:$F,0))) | J9: =IF($D9="","",INDEX('02_能力差距自评'!$N:$N,MATCH($D9,'02_能力差距自评'!$F:$F,0))) | K9: =IF($D9="","",INDEX('02_能力差距自评'!$O:$O,MATCH($D9,'02_能力差距自评'!$F:$F,0))) | L9: =IF($D9="","",INDEX('02_能力差距自评'!$I:$I,MATCH($D9,'02_能力差距自评'!$F:$F,0))) | M9: =IF($D9="","",$E9) | N9: =IF($D9="","",INDEX('02_能力差距自评'!$J:$J,MATCH($D9,'02_能力差距自评'!$F:$F,0))) | O9: =IF($D9="","",INDEX('02_能力差距自评'!$K:$K,MATCH($D9,'02_能力差距自评'!$F:$F,0))) | S9: =IF($D9="","","未开始")
A10: =IF($D10="","","LP"&TEXT(ROWS($A$2:A10),"000")) | B10: =IF($D10="","",IFERROR(INDEX('02_能力差距自评'!$Q:$Q,MATCH($D10,'02_能力差距自评'!$F:$F,0)),"")) | C10: =IF($D10="","",IFERROR(INDEX('02_能力差距自评'!$R:$R,MATCH($D10,'02_能力差距自评'!$F:$F,0)),"")) | D10: =IFERROR(INDEX('02_能力差距自评'!$F$2:$F$311,MATCH(ROWS($D$2:D10),'02_能力差距自评'!$W$2:$W$311,0)),"") | E10: =IF($D10="","",INDEX('02_能力差距自评'!$G:$G,MATCH($D10,'02_能力差距自评'!$F:$F,0))) | F10: =IF($D10="","",INDEX('02_能力差距自评'!$C:$C,MATCH($D10,'02_能力差距自评'!$F:$F,0))) | G10: =IF($D10="","",INDEX('02_能力差距自评'!$E:$E,MATCH($D10,'02_能力差距自评'!$F:$F,0))) | H10: =IF($D10="","",INDEX('02_能力差距自评'!$L:$L,MATCH($D10,'02_能力差距自评'!$F:$F,0))) | I10: =IF($D10="","",INDEX('02_能力差距自评'!$M:$M,MATCH($D10,'02_能力差距自评'!$F:$F,0))) | J10: =IF($D10="","",INDEX('02_能力差距自评'!$N:$N,MATCH($D10,'02_能力差距自评'!$F:$F,0))) | K10: =IF($D10="","",INDEX('02_能力差距自评'!$O:$O,MATCH($D10,'02_能力差距自评'!$F:$F,0))) | L10: =IF($D10="","",INDEX('02_能力差距自评'!$I:$I,MATCH($D10,'02_能力差距自评'!$F:$F,0))) | M10: =IF($D10="","",$E10) | N10: =IF($D10="","",INDEX('02_能力差距自评'!$J:$J,MATCH($D10,'02_能力差距自评'!$F:$F,0))) | O10: =IF($D10="","",INDEX('02_能力差距自评'!$K:$K,MATCH($D10,'02_能力差距自评'!$F:$F,0))) | S10: =IF($D10="","","未开始")
A11: =IF($D11="","","LP"&TEXT(ROWS($A$2:A11),"000")) | B11: =IF($D11="","",IFERROR(INDEX('02_能力差距自评'!$Q:$Q,MATCH($D11,'02_能力差距自评'!$F:$F,0)),"")) | C11: =IF($D11="","",IFERROR(INDEX('02_能力差距自评'!$R:$R,MATCH($D11,'02_能力差距自评'!$F:$F,0)),"")) | D11: =IFERROR(INDEX('02_能力差距自评'!$F$2:$F$311,MATCH(ROWS($D$2:D11),'02_能力差距自评'!$W$2:$W$311,0)),"") | E11: =IF($D11="","",INDEX('02_能力差距自评'!$G:$G,MATCH($D11,'02_能力差距自评'!$F:$F,0))) | F11: =IF($D11="","",INDEX('02_能力差距自评'!$C:$C,MATCH($D11,'02_能力差距自评'!$F:$F,0))) | G11: =IF($D11="","",INDEX('02_能力差距自评'!$E:$E,MATCH($D11,'02_能力差距自评'!$F:$F,0))) | H11: =IF($D11="","",INDEX('02_能力差距自评'!$L:$L,MATCH($D11,'02_能力差距自评'!$F:$F,0))) | I11: =IF($D11="","",INDEX('02_能力差距自评'!$M:$M,MATCH($D11,'02_能力差距自评'!$F:$F,0))) | J11: =IF($D11="","",INDEX('02_能力差距自评'!$N:$N,MATCH($D11,'02_能力差距自评'!$F:$F,0))) | K11: =IF($D11="","",INDEX('02_能力差距自评'!$O:$O,MATCH($D11,'02_能力差距自评'!$F:$F,0))) | L11: =IF($D11="","",INDEX('02_能力差距自评'!$I:$I,MATCH($D11,'02_能力差距自评'!$F:$F,0))) | M11: =IF($D11="","",$E11) | N11: =IF($D11="","",INDEX('02_能力差距自评'!$J:$J,MATCH($D11,'02_能力差距自评'!$F:$F,0))) | O11: =IF($D11="","",INDEX('02_能力差距自评'!$K:$K,MATCH($D11,'02_能力差距自评'!$F:$F,0))) | S11: =IF($D11="","","未开始")
A12: =IF($D12="","","LP"&TEXT(ROWS($A$2:A12),"000")) | B12: =IF($D12="","",IFERROR(INDEX('02_能力差距自评'!$Q:$Q,MATCH($D12,'02_能力差距自评'!$F:$F,0)),"")) | C12: =IF($D12="","",IFERROR(INDEX('02_能力差距自评'!$R:$R,MATCH($D12,'02_能力差距自评'!$F:$F,0)),"")) | D12: =IFERROR(INDEX('02_能力差距自评'!$F$2:$F$311,MATCH(ROWS($D$2:D12),'02_能力差距自评'!$W$2:$W$311,0)),"") | E12: =IF($D12="","",INDEX('02_能力差距自评'!$G:$G,MATCH($D12,'02_能力差距自评'!$F:$F,0))) | F12: =IF($D12="","",INDEX('02_能力差距自评'!$C:$C,MATCH($D12,'02_能力差距自评'!$F:$F,0))) | G12: =IF($D12="","",INDEX('02_能力差距自评'!$E:$E,MATCH($D12,'02_能力差距自评'!$F:$F,0))) | H12: =IF($D12="","",INDEX('02_能力差距自评'!$L:$L,MATCH($D12,'02_能力差距自评'!$F:$F,0))) | I12: =IF($D12="","",INDEX('02_能力差距自评'!$M:$M,MATCH($D12,'02_能力差距自评'!$F:$F,0))) | J12: =IF($D12="","",INDEX('02_能力差距自评'!$N:$N,MATCH($D12,'02_能力差距自评'!$F:$F,0))) | K12: =IF($D12="","",INDEX('02_能力差距自评'!$O:$O,MATCH($D12,'02_能力差距自评'!$F:$F,0))) | L12: =IF($D12="","",INDEX('02_能力差距自评'!$I:$I,MATCH($D12,'02_能力差距自评'!$F:$F,0))) | M12: =IF($D12="","",$E12) | N12: =IF($D12="","",INDEX('02_能力差距自评'!$J:$J,MATCH($D12,'02_能力差距自评'!$F:$F,0))) | O12: =IF($D12="","",INDEX('02_能力差距自评'!$K:$K,MATCH($D12,'02_能力差距自评'!$F:$F,0))) | S12: =IF($D12="","","未开始")
A13: =IF($D13="","","LP"&TEXT(ROWS($A$2:A13),"000")) | B13: =IF($D13="","",IFERROR(INDEX('02_能力差距自评'!$Q:$Q,MATCH($D13,'02_能力差距自评'!$F:$F,0)),"")) | C13: =IF($D13="","",IFERROR(INDEX('02_能力差距自评'!$R:$R,MATCH($D13,'02_能力差距自评'!$F:$F,0)),"")) | D13: =IFERROR(INDEX('02_能力差距自评'!$F$2:$F$311,MATCH(ROWS($D$2:D13),'02_能力差距自评'!$W$2:$W$311,0)),"") | E13: =IF($D13="","",INDEX('02_能力差距自评'!$G:$G,MATCH($D13,'02_能力差距自评'!$F:$F,0))) | F13: =IF($D13="","",INDEX('02_能力差距自评'!$C:$C,MATCH($D13,'02_能力差距自评'!$F:$F,0))) | G13: =IF($D13="","",INDEX('02_能力差距自评'!$E:$E,MATCH($D13,'02_能力差距自评'!$F:$F,0))) | H13: =IF($D13="","",INDEX('02_能力差距自评'!$L:$L,MATCH($D13,'02_能力差距自评'!$F:$F,0))) | I13: =IF($D13="","",INDEX('02_能力差距自评'!$M:$M,MATCH($D13,'02_能力差距自评'!$F:$F,0))) | J13: =IF($D13="","",INDEX('02_能力差距自评'!$N:$N,MATCH($D13,'02_能力差距自评'!$F:$F,0))) | K13: =IF($D13="","",INDEX('02_能力差距自评'!$O:$O,MATCH($D13,'02_能力差距自评'!$F:$F,0))) | L13: =IF($D13="","",INDEX('02_能力差距自评'!$I:$I,MATCH($D13,'02_能力差距自评'!$F:$F,0))) | M13: =IF($D13="","",$E13) | N13: =IF($D13="","",INDEX('02_能力差距自评'!$J:$J,MATCH($D13,'02_能力差距自评'!$F:$F,0))) | O13: =IF($D13="","",INDEX('02_能力差距自评'!$K:$K,MATCH($D13,'02_能力差距自评'!$F:$F,0))) | S13: =IF($D13="","","未开始")
... A350: =IF($D350="","","LP"&TEXT(ROWS($A$2:A350),"000")) | B350: =IF($D350="","",IFERROR(INDEX('02_能力差距自评'!$Q:$Q,MATCH($D350,'02_能力差距自评'!$F:$F,0)),"")) | C350: =IF($D350="","",IFERROR(INDEX('02_能力差距自评'!$R:$R,MATCH($D350,'02_能力差距自评'!$F:$F,0)),"")) | D350: =IFERROR(INDEX('02_能力差距自评'!$F$2:$F$311,MATCH(ROWS($D$2:D350),'02_能力差距自评'!$W$2:$W$311,0)),"") | E350: =IF($D350="","",INDEX('02_能力差距自评'!$G:$G,MATCH($D350,'02_能力差距自评'!$F:$F,0))) | F350: =IF($D350="","",INDEX('02_能力差距自评'!$C:$C,MATCH($D350,'02_能力差距自评'!$F:$F,0))) | G350: =IF($D350="","",INDEX('02_能力差距自评'!$E:$E,MATCH($D350,'02_能力差距自评'!$F:$F,0))) | H350: =IF($D350="","",INDEX('02_能力差距自评'!$L:$L,MATCH($D350,'02_能力差距自评'!$F:$F,0))) | I350: =IF($D350="","",INDEX('02_能力差距自评'!$M:$M,MATCH($D350,'02_能力差距自评'!$F:$F,0))) | J350: =IF($D350="","",INDEX('02_能力差距自评'!$N:$N,MATCH($D350,'02_能力差距自评'!$F:$F,0))) | K350: =IF($D350="","",INDEX('02_能力差距自评'!$O:$O,MATCH($D350,'02_能力差距自评'!$F:$F,0))) | L350: =IF($D350="","",INDEX('02_能力差距自评'!$I:$I,MATCH($D350,'02_能力差距自评'!$F:$F,0))) | M350: =IF($D350="","",$E350) | N350: =IF($D350="","",INDEX('02_能力差距自评'!$J:$J,MATCH($D350,'02_能力差距自评'!$F:$F,0))) | O350: =IF($D350="","",INDEX('02_能力差距自评'!$K:$K,MATCH($D350,'02_能力差距自评'!$F:$F,0))) | S350: =IF($D350="","","未开始")

Sheet 04_学习执行跟踪
A1: 计划编号 | B1: 能力编码 | C1: 一级能力域 | D1: 二级能力项 | E1: 三级能力项 | F1: 学习材料 | G1: 预期输出 / 验收方式 | H1: 预计耗时(h) | I1: 计划开始 | J1: 计划截止 | K1: 年度计划状态 | L1: 执行状态 | M1: 实际开始 | N1: 实际完成 | O1: 实际耗时(h) | P1: 证据链接 / 文件 | Q1: 完成质量 | R1: 复盘结论 | S1: 下步动作 | T1: 备注
A2: =IF('03_年度学习计划'!$A2="","",'03_年度学习计划'!$A2) | B2: =IF($A2="","",'03_年度学习计划'!$D2) | C2: =IF($A2="","",'03_年度学习计划'!$F2) | D2: =IF($A2="","",'03_年度学习计划'!$G2) | E2: =IF($A2="","",'03_年度学习计划'!$E2) | F2: =IF($A2="","",'03_年度学习计划'!$L2) | G2: =IF($A2="","",'03_年度学习计划'!$N2) | H2: =IF($A2="","",'03_年度学习计划'!$O2) | I2: =IF($A2="","",'03_年度学习计划'!$P2) | J2: =IF($A2="","",'03_年度学习计划'!$Q2) | K2: =IF($A2="","",'03_年度学习计划'!$S2) | L2: =IF($A2="","","未开始")
A3: =IF('03_年度学习计划'!$A3="","",'03_年度学习计划'!$A3) | B3: =IF($A3="","",'03_年度学习计划'!$D3) | C3: =IF($A3="","",'03_年度学习计划'!$F3) | D3: =IF($A3="","",'03_年度学习计划'!$G3) | E3: =IF($A3="","",'03_年度学习计划'!$E3) | F3: =IF($A3="","",'03_年度学习计划'!$L3) | G3: =IF($A3="","",'03_年度学习计划'!$N3) | H3: =IF($A3="","",'03_年度学习计划'!$O3) | I3: =IF($A3="","",'03_年度学习计划'!$P3) | J3: =IF($A3="","",'03_年度学习计划'!$Q3) | K3: =IF($A3="","",'03_年度学习计划'!$S3) | L3: =IF($A3="","","未开始")
A4: =IF('03_年度学习计划'!$A4="","",'03_年度学习计划'!$A4) | B4: =IF($A4="","",'03_年度学习计划'!$D4) | C4: =IF($A4="","",'03_年度学习计划'!$F4) | D4: =IF($A4="","",'03_年度学习计划'!$G4) | E4: =IF($A4="","",'03_年度学习计划'!$E4) | F4: =IF($A4="","",'03_年度学习计划'!$L4) | G4: =IF($A4="","",'03_年度学习计划'!$N4) | H4: =IF($A4="","",'03_年度学习计划'!$O4) | I4: =IF($A4="","",'03_年度学习计划'!$P4) | J4: =IF($A4="","",'03_年度学习计划'!$Q4) | K4: =IF($A4="","",'03_年度学习计划'!$S4) | L4: =IF($A4="","","未开始")
A5: =IF('03_年度学习计划'!$A5="","",'03_年度学习计划'!$A5) | B5: =IF($A5="","",'03_年度学习计划'!$D5) | C5: =IF($A5="","",'03_年度学习计划'!$F5) | D5: =IF($A5="","",'03_年度学习计划'!$G5) | E5: =IF($A5="","",'03_年度学习计划'!$E5) | F5: =IF($A5="","",'03_年度学习计划'!$L5) | G5: =IF($A5="","",'03_年度学习计划'!$N5) | H5: =IF($A5="","",'03_年度学习计划'!$O5) | I5: =IF($A5="","",'03_年度学习计划'!$P5) | J5: =IF($A5="","",'03_年度学习计划'!$Q5) | K5: =IF($A5="","",'03_年度学习计划'!$S5) | L5: =IF($A5="","","未开始")
A6: =IF('03_年度学习计划'!$A6="","",'03_年度学习计划'!$A6) | B6: =IF($A6="","",'03_年度学习计划'!$D6) | C6: =IF($A6="","",'03_年度学习计划'!$F6) | D6: =IF($A6="","",'03_年度学习计划'!$G6) | E6: =IF($A6="","",'03_年度学习计划'!$E6) | F6: =IF($A6="","",'03_年度学习计划'!$L6) | G6: =IF($A6="","",'03_年度学习计划'!$N6) | H6: =IF($A6="","",'03_年度学习计划'!$O6) | I6: =IF($A6="","",'03_年度学习计划'!$P6) | J6: =IF($A6="","",'03_年度学习计划'!$Q6) | K6: =IF($A6="","",'03_年度学习计划'!$S6) | L6: =IF($A6="","","未开始")
A7: =IF('03_年度学习计划'!$A7="","",'03_年度学习计划'!$A7) | B7: =IF($A7="","",'03_年度学习计划'!$D7) | C7: =IF($A7="","",'03_年度学习计划'!$F7) | D7: =IF($A7="","",'03_年度学习计划'!$G7) | E7: =IF($A7="","",'03_年度学习计划'!$E7) | F7: =IF($A7="","",'03_年度学习计划'!$L7) | G7: =IF($A7="","",'03_年度学习计划'!$N7) | H7: =IF($A7="","",'03_年度学习计划'!$O7) | I7: =IF($A7="","",'03_年度学习计划'!$P7) | J7: =IF($A7="","",'03_年度学习计划'!$Q7) | K7: =IF($A7="","",'03_年度学习计划'!$S7) | L7: =IF($A7="","","未开始")
A8: =IF('03_年度学习计划'!$A8="","",'03_年度学习计划'!$A8) | B8: =IF($A8="","",'03_年度学习计划'!$D8) | C8: =IF($A8="","",'03_年度学习计划'!$F8) | D8: =IF($A8="","",'03_年度学习计划'!$G8) | E8: =IF($A8="","",'03_年度学习计划'!$E8) | F8: =IF($A8="","",'03_年度学习计划'!$L8) | G8: =IF($A8="","",'03_年度学习计划'!$N8) | H8: =IF($A8="","",'03_年度学习计划'!$O8) | I8: =IF($A8="","",'03_年度学习计划'!$P8) | J8: =IF($A8="","",'03_年度学习计划'!$Q8) | K8: =IF($A8="","",'03_年度学习计划'!$S8) | L8: =IF($A8="","","未开始")
A9: =IF('03_年度学习计划'!$A9="","",'03_年度学习计划'!$A9) | B9: =IF($A9="","",'03_年度学习计划'!$D9) | C9: =IF($A9="","",'03_年度学习计划'!$F9) | D9: =IF($A9="","",'03_年度学习计划'!$G9) | E9: =IF($A9="","",'03_年度学习计划'!$E9) | F9: =IF($A9="","",'03_年度学习计划'!$L9) | G9: =IF($A9="","",'03_年度学习计划'!$N9) | H9: =IF($A9="","",'03_年度学习计划'!$O9) | I9: =IF($A9="","",'03_年度学习计划'!$P9) | J9: =IF($A9="","",'03_年度学习计划'!$Q9) | K9: =IF($A9="","",'03_年度学习计划'!$S9) | L9: =IF($A9="","","未开始")
A10: =IF('03_年度学习计划'!$A10="","",'03_年度学习计划'!$A10) | B10: =IF($A10="","",'03_年度学习计划'!$D10) | C10: =IF($A10="","",'03_年度学习计划'!$F10) | D10: =IF($A10="","",'03_年度学习计划'!$G10) | E10: =IF($A10="","",'03_年度学习计划'!$E10) | F10: =IF($A10="","",'03_年度学习计划'!$L10) | G10: =IF($A10="","",'03_年度学习计划'!$N10) | H10: =IF($A10="","",'03_年度学习计划'!$O10) | I10: =IF($A10="","",'03_年度学习计划'!$P10) | J10: =IF($A10="","",'03_年度学习计划'!$Q10) | K10: =IF($A10="","",'03_年度学习计划'!$S10) | L10: =IF($A10="","","未开始")
A11: =IF('03_年度学习计划'!$A11="","",'03_年度学习计划'!$A11) | B11: =IF($A11="","",'03_年度学习计划'!$D11) | C11: =IF($A11="","",'03_年度学习计划'!$F11) | D11: =IF($A11="","",'03_年度学习计划'!$G11) | E11: =IF($A11="","",'03_年度学习计划'!$E11) | F11: =IF($A11="","",'03_年度学习计划'!$L11) | G11: =IF($A11="","",'03_年度学习计划'!$N11) | H11: =IF($A11="","",'03_年度学习计划'!$O11) | I11: =IF($A11="","",'03_年度学习计划'!$P11) | J11: =IF($A11="","",'03_年度学习计划'!$Q11) | K11: =IF($A11="","",'03_年度学习计划'!$S11) | L11: =IF($A11="","","未开始")
A12: =IF('03_年度学习计划'!$A12="","",'03_年度学习计划'!$A12) | B12: =IF($A12="","",'03_年度学习计划'!$D12) | C12: =IF($A12="","",'03_年度学习计划'!$F12) | D12: =IF($A12="","",'03_年度学习计划'!$G12) | E12: =IF($A12="","",'03_年度学习计划'!$E12) | F12: =IF($A12="","",'03_年度学习计划'!$L12) | G12: =IF($A12="","",'03_年度学习计划'!$N12) | H12: =IF($A12="","",'03_年度学习计划'!$O12) | I12: =IF($A12="","",'03_年度学习计划'!$P12) | J12: =IF($A12="","",'03_年度学习计划'!$Q12) | K12: =IF($A12="","",'03_年度学习计划'!$S12) | L12: =IF($A12="","","未开始")
A13: =IF('03_年度学习计划'!$A13="","",'03_年度学习计划'!$A13) | B13: =IF($A13="","",'03_年度学习计划'!$D13) | C13: =IF($A13="","",'03_年度学习计划'!$F13) | D13: =IF($A13="","",'03_年度学习计划'!$G13) | E13: =IF($A13="","",'03_年度学习计划'!$E13) | F13: =IF($A13="","",'03_年度学习计划'!$L13) | G13: =IF($A13="","",'03_年度学习计划'!$N13) | H13: =IF($A13="","",'03_年度学习计划'!$O13) | I13: =IF($A13="","",'03_年度学习计划'!$P13) | J13: =IF($A13="","",'03_年度学习计划'!$Q13) | K13: =IF($A13="","",'03_年度学习计划'!$S13) | L13: =IF($A13="","","未开始")
... A201: =IF('03_年度学习计划'!$A201="","",'03_年度学习计划'!$A201) | B201: =IF($A201="","",'03_年度学习计划'!$D201) | C201: =IF($A201="","",'03_年度学习计划'!$F201) | D201: =IF($A201="","",'03_年度学习计划'!$G201) | E201: =IF($A201="","",'03_年度学习计划'!$E201) | F201: =IF($A201="","",'03_年度学习计划'!$L201) | G201: =IF($A201="","",'03_年度学习计划'!$N201) | H201: =IF($A201="","",'03_年度学习计划'!$O201) | I201: =IF($A201="","",'03_年度学习计划'!$P201) | J201: =IF($A201="","",'03_年度学习计划'!$Q201) | K201: =IF($A201="","",'03_年度学习计划'!$S201) | L201: =IF($A201="","","未开始")

Sheet 05_月度复盘
A1: 月份 | B1: 计划项数 | C1: 已完成数 | D1: 完成率 | E1: 预计耗时(h) | F1: 实际耗时(h) | G1: 主要产出 | H1: 主要问题 | I1: 下月重点 | J1: 备注
A2: 第1月 | B2: =COUNTIFS('03_年度学习计划'!$C$2:$C$201,A2,'03_年度学习计划'!$D$2:$D$201,"<>") -> 0 | C2: =SUMPRODUCT(('03_年度学习计划'!$C$2:$C$201=A2)*('03_年度学习计划'!$D$2:$D$201<>"")*('04_学习执行跟踪'!$L$2:$L$201="已完成")) -> 0 | D2: =IFERROR(C2/B2,0) -> 0 | E2: =SUMIF('03_年度学习计划'!$C$2:$C$201,A2,'03_年度学习计划'!$O$2:$O$201) -> 0 | F2: =SUMPRODUCT(('03_年度学习计划'!$C$2:$C$201=A2)*('04_学习执行跟踪'!$O$2:$O$201)) -> 0
A3: 第2月 | B3: =COUNTIFS('03_年度学习计划'!$C$2:$C$201,A3,'03_年度学习计划'!$D$2:$D$201,"<>") -> 0 | C3: =SUMPRODUCT(('03_年度学习计划'!$C$2:$C$201=A3)*('03_年度学习计划'!$D$2:$D$201<>"")*('04_学习执行跟踪'!$L$2:$L$201="已完成")) -> 0 | D3: =IFERROR(C3/B3,0) -> 0 | E3: =SUMIF('03_年度学习计划'!$C$2:$C$201,A3,'03_年度学习计划'!$O$2:$O$201) -> 0 | F3: =SUMPRODUCT(('03_年度学习计划'!$C$2:$C$201=A3)*('04_学习执行跟踪'!$O$2:$O$201)) -> 0
A4: 第3月 | B4: =COUNTIFS('03_年度学习计划'!$C$2:$C$201,A4,'03_年度学习计划'!$D$2:$D$201,"<>") -> 0 | C4: =SUMPRODUCT(('03_年度学习计划'!$C$2:$C$201=A4)*('03_年度学习计划'!$D$2:$D$201<>"")*('04_学习执行跟踪'!$L$2:$L$201="已完成")) -> 0 | D4: =IFERROR(C4/B4,0) -> 0 | E4: =SUMIF('03_年度学习计划'!$C$2:$C$201,A4,'03_年度学习计划'!$O$2:$O$201) -> 0 | F4: =SUMPRODUCT(('03_年度学习计划'!$C$2:$C$201=A4)*('04_学习执行跟踪'!$O$2:$O$201)) -> 0
A5: 第4月 | B5: =COUNTIFS('03_年度学习计划'!$C$2:$C$201,A5,'03_年度学习计划'!$D$2:$D$201,"<>") -> 0 | C5: =SUMPRODUCT(('03_年度学习计划'!$C$2:$C$201=A5)*('03_年度学习计划'!$D$2:$D$201<>"")*('04_学习执行跟踪'!$L$2:$L$201="已完成")) -> 0 | D5: =IFERROR(C5/B5,0) -> 0 | E5: =SUMIF('03_年度学习计划'!$C$2:$C$201,A5,'03_年度学习计划'!$O$2:$O$201) -> 0 | F5: =SUMPRODUCT(('03_年度学习计划'!$C$2:$C$201=A5)*('04_学习执行跟踪'!$O$2:$O$201)) -> 0
A6: 第5月 | B6: =COUNTIFS('03_年度学习计划'!$C$2:$C$201,A6,'03_年度学习计划'!$D$2:$D$201,"<>") -> 0 | C6: =SUMPRODUCT(('03_年度学习计划'!$C$2:$C$201=A6)*('03_年度学习计划'!$D$2:$D$201<>"")*('04_学习执行跟踪'!$L$2:$L$201="已完成")) -> 0 | D6: =IFERROR(C6/B6,0) -> 0 | E6: =SUMIF('03_年度学习计划'!$C$2:$C$201,A6,'03_年度学习计划'!$O$2:$O$201) -> 0 | F6: =SUMPRODUCT(('03_年度学习计划'!$C$2:$C$201=A6)*('04_学习执行跟踪'!$O$2:$O$201)) -> 0
A7: 第6月 | B7: =COUNTIFS('03_年度学习计划'!$C$2:$C$201,A7,'03_年度学习计划'!$D$2:$D$201,"<>") -> 0 | C7: =SUMPRODUCT(('03_年度学习计划'!$C$2:$C$201=A7)*('03_年度学习计划'!$D$2:$D$201<>"")*('04_学习执行跟踪'!$L$2:$L$201="已完成")) -> 0 | D7: =IFERROR(C7/B7,0) -> 0 | E7: =SUMIF('03_年度学习计划'!$C$2:$C$201,A7,'03_年度学习计划'!$O$2:$O$201) -> 0 | F7: =SUMPRODUCT(('03_年度学习计划'!$C$2:$C$201=A7)*('04_学习执行跟踪'!$O$2:$O$201)) -> 0
A8: 第7月 | B8: =COUNTIFS('03_年度学习计划'!$C$2:$C$201,A8,'03_年度学习计划'!$D$2:$D$201,"<>") -> 0 | C8: =SUMPRODUCT(('03_年度学习计划'!$C$2:$C$201=A8)*('03_年度学习计划'!$D$2:$D$201<>"")*('04_学习执行跟踪'!$L$2:$L$201="已完成")) -> 0 | D8: =IFERROR(C8/B8,0) -> 0 | E8: =SUMIF('03_年度学习计划'!$C$2:$C$201,A8,'03_年度学习计划'!$O$2:$O$201) -> 0 | F8: =SUMPRODUCT(('03_年度学习计划'!$C$2:$C$201=A8)*('04_学习执行跟踪'!$O$2:$O$201)) -> 0
A9: 第8月 | B9: =COUNTIFS('03_年度学习计划'!$C$2:$C$201,A9,'03_年度学习计划'!$D$2:$D$201,"<>") -> 0 | C9: =SUMPRODUCT(('03_年度学习计划'!$C$2:$C$201=A9)*('03_年度学习计划'!$D$2:$D$201<>"")*('04_学习执行跟踪'!$L$2:$L$201="已完成")) -> 0 | D9: =IFERROR(C9/B9,0) -> 0 | E9: =SUMIF('03_年度学习计划'!$C$2:$C$201,A9,'03_年度学习计划'!$O$2:$O$201) -> 0 | F9: =SUMPRODUCT(('03_年度学习计划'!$C$2:$C$201=A9)*('04_学习执行跟踪'!$O$2:$O$201)) -> 0
A10: 第9月 | B10: =COUNTIFS('03_年度学习计划'!$C$2:$C$201,A10,'03_年度学习计划'!$D$2:$D$201,"<>") -> 0 | C10: =SUMPRODUCT(('03_年度学习计划'!$C$2:$C$201=A10)*('03_年度学习计划'!$D$2:$D$201<>"")*('04_学习执行跟踪'!$L$2:$L$201="已完成")) -> 0 | D10: =IFERROR(C10/B10,0) -> 0 | E10: =SUMIF('03_年度学习计划'!$C$2:$C$201,A10,'03_年度学习计划'!$O$2:$O$201) -> 0 | F10: =SUMPRODUCT(('03_年度学习计划'!$C$2:$C$201=A10)*('04_学习执行跟踪'!$O$2:$O$201)) -> 0
A11: 第10月 | B11: =COUNTIFS('03_年度学习计划'!$C$2:$C$201,A11,'03_年度学习计划'!$D$2:$D$201,"<>") -> 0 | C11: =SUMPRODUCT(('03_年度学习计划'!$C$2:$C$201=A11)*('03_年度学习计划'!$D$2:$D$201<>"")*('04_学习执行跟踪'!$L$2:$L$201="已完成")) -> 0 | D11: =IFERROR(C11/B11,0) -> 0 | E11: =SUMIF('03_年度学习计划'!$C$2:$C$201,A11,'03_年度学习计划'!$O$2:$O$201) -> 0 | F11: =SUMPRODUCT(('03_年度学习计划'!$C$2:$C$201=A11)*('04_学习执行跟踪'!$O$2:$O$201)) -> 0
A12: 第11月 | B12: =COUNTIFS('03_年度学习计划'!$C$2:$C$201,A12,'03_年度学习计划'!$D$2:$D$201,"<>") -> 0 | C12: =SUMPRODUCT(('03_年度学习计划'!$C$2:$C$201=A12)*('03_年度学习计划'!$D$2:$D$201<>"")*('04_学习执行跟踪'!$L$2:$L$201="已完成")) -> 0 | D12: =IFERROR(C12/B12,0) -> 0 | E12: =SUMIF('03_年度学习计划'!$C$2:$C$201,A12,'03_年度学习计划'!$O$2:$O$201) -> 0 | F12: =SUMPRODUCT(('03_年度学习计划'!$C$2:$C$201=A12)*('04_学习执行跟踪'!$O$2:$O$201)) -> 0
A13: 第12月 | B13: =COUNTIFS('03_年度学习计划'!$C$2:$C$201,A13,'03_年度学习计划'!$D$2:$D$201,"<>") -> 0 | C13: =SUMPRODUCT(('03_年度学习计划'!$C$2:$C$201=A13)*('03_年度学习计划'!$D$2:$D$201<>"")*('04_学习执行跟踪'!$L$2:$L$201="已完成")) -> 0 | D13: =IFERROR(C13/B13,0) -> 0 | E13: =SUMIF('03_年度学习计划'!$C$2:$C$201,A13,'03_年度学习计划'!$O$2:$O$201) -> 0 | F13: =SUMPRODUCT(('03_年度学习计划'!$C$2:$C$201=A13)*('04_学习执行跟踪'!$O$2:$O$201)) -> 0

Sheet 06_学习材料索引
A1: 材料编码 | B1: 材料名称 | C1: 材料类型 | D1: 材料来源 / 附件名 | E1: 用途说明 | F1: 材料状态
A2: P01-M001 | B2: 产品体系材料 | C2: 产品/项目材料 | D2: TDC、TDH、ArgoDB、TDS 产品介绍、官网资料、项目方案、大赛材料 | E2: 用于理解 TDC、TDH、ArgoDB、TDS 产品定位、能力边界、产品组合关系和典型客户场景；支撑产品体系认知、选型判断和方案表达。 | F2: 已提供附件 / 官网与项目材料，建议定期更新
A3: P01-M002 | B3: TDH 部署 / 运维材料 | C3: 部署/运维手册 | D3: TDH 部署手册、TDH 安装部署大赛材料、TDH 运维手册 | E3: 用于 TDH 环境检查、标准部署、组件验证、Manager 使用、HDFS / YARN / ZK / Kafka 等组件认知和基础运维训练。 | F3: 已提供附件
A4: P01-M003 | B4: TDC 部署 / 租户材料 | C4: 部署/租户材料 | D4: TDC 部署手册、TDC 安装部署大赛材料、TDC 租户与产品部署运维材料 | E4: 用于 TDC 标准部署、租户配置、产品纳管、资源隔离、应用上架和多租户平台能力训练。 | F4: 已提供附件
A5: P01-M004 | B5: ArgoDB 材料 | C5: 产品使用/性能材料 | D5: ArgoDB 快速入门、ArgoDB 6.1 新功能材料 | E5: 用于 ArgoDB 安装连接、建库建表、分区分桶、批量 / 实时写入、SQL 优化、实时湖仓和性能验证训练。 | F5: 已提供附件
A6: P01-M005 | B6: TDS 数据开发材料 | C6: 数据开发材料 | D6: TDS 数据开发快速入门、TDS 推广介绍 | E6: 用于 TDS 数据源配置、数据同步、SQLBook、Workflow、Transporter、脱敏任务和数据开发流程训练。 | F6: 已提供附件
A7: P01-M006 | B7: TDS 数据治理材料 | C7: 数据治理材料 | D7: TDS 数据治理快速入门 | E7: 用于 TDS 数据治理能力训练，包括元数据、血缘、数据标准、质量规则、落标检查、分类分级和治理任务运维。 | F7: 已提供附件
A8: P01-M007 | B8: 数仓 / 湖仓材料 | C8: 建模/湖仓材料 | D8: TDC 大赛湖仓方案、ArgoDB 实时湖仓材料、TDS 建模章节 | E8: 用于数仓 / 湖仓建模、ODS/DWD/DWS/ADS 分层、T+0/T+1 数据流转、湖仓一体和数据共享方案训练。 | F8: 已提供附件
A9: P01-M008 | B9: 数据集成与实时同步材料 | C9: 数据集成/POC材料 | D9: 南京医药实时同步工具 POC、TDS Transporter、CDC / DDL / 一致性验证材料 | E9: 用于批量同步、增量同步、CDC、DDL 变更、数据一致性校验和实时同步 POC 验证训练。 | F9: 已提供附件
A10: P01-M009 | B10: 资源规划 / 性能 / 稳定性材料 | C10: 性能/稳定性材料 | D10: TDH / TDC 部署手册、大赛验证报告、ArgoDB 性能材料 | E10: 用于资源规划、容量估算、性能验证、扩缩容、高可用、巡检、压测和稳定性基础训练。 | F10: 已提供附件
A11: P01-M010 | B11: 数据安全 / 权限 / 合规材料 | C11: 安全/权限材料 | D11: TDS 权限、分类分级、脱敏、TDC 租户隔离、TDH Kerberos / Guardian 等材料 | E11: 用于账号角色、租户隔离、库表权限、分类分级、脱敏、审计、数据共享审批和合规检查训练。 | F11: 已提供附件
A12: P01-M011 | B12: Data Infra 项目案例 / POC / 复盘材料 | C12: 项目案例/复盘材料 | D12: 内部项目方案、POC 材料、客户案例、项目复盘、问题处理案例 | E12: 用于支撑 Data Infra 场景适配、方案验证、经验沉淀和高阶方法论输出；建议按项目沉淀方案、验证过程、问题清单和复盘结论。 | F12: 内部待补 / 项目沉淀
... A96: C03-M013 | B96: 内部待补：问题复盘与 FAQ 模板 | C96: 内部模板 | D96: 内部待补 | E96: 用于沉淀问题现象、原因、处理步骤、预防措施、相关材料和责任边界。 | F96: 建议由团队维护

Sheet 07_填表字典
A1: 掌握度 | B1: 含义 | C1: 职级参考 | D1: 说明 | F1: 优先级 | H1: 是否纳入计划 | J1: 计划季度 | L1: 月份 | N1: 完成状态
A2: 0 | B2: 未接触 / 不具备可验证输出 | C2: - | F2: 高 | H2: 是 | J2: Q1 | L2: 第1月 | N2: 未开始
A3: 1 | B3: 了解概念，需要他人指导或协助 | C3: 入门 | F3: 中 | H3: 否 | J3: Q2 | L3: 第2月 | N3: 进行中
A4: 2 | B4: 标准场景可独立执行，有基础实操输出 | C4: P4 | F4: 低 | J4: Q3 | L4: 第3月 | N4: 已完成
A5: 3 | B5: 能处理常见问题，能闭环基础异常 | C5: P5 | F5: 暂缓 | J5: Q4 | L5: 第4月 | N5: 延期
A6: 4 | B6: 能设计方案、组织实施并处理复杂场景 | C6: P6 | L6: 第5月 | N6: 暂停
A7: 5 | B7: 能主导复杂项目，沉淀规范、模板和方法论 | C7: P7-P8 | L7: 第6月 | N7: 取消
L8: 第7月
L9: 第8月
L10: 第9月
L11: 第10月
L12: 第11月
L13: 第12月
